Workbook

Sheet Buildings
A1: Agency | B1: Site / Building | C1: Address | D1: Borough | E1: ZIP | F1: Council District | G1: Gross Sq Ft | H1: Roof Condition | I1: Roof Age | J1: Solar Status | K1: Other Sustainability Projects | L1: Disadvantaged Community | M1: Latest LL24 Report Yr | N1: BIN | O1: BBL | P1: Lat | Q1: Long
A2: ACS | B2: Children Pride Early Learning Center | C2: 800 Concourse Village East | D2: Bronx | E2: 10451 | F2: 1 | G2: 436836 | H2: Poor | I2: 20 years or more | J2: Not Solar-Ready | L2: No | M2: 2024 | N2: 2001910 | O2: 2024200040 | P2: 40.82388 | Q2: -73.919379
A3: ACS | B3: Crossroads Juvenile Center | C3: 17 Bristol St | D3: Brooklyn | E3: 11212 | F3: 41 | G3: 105223 | H3: Between Good and Fair | I3: 20 years or more | J3: Not Solar-Ready | L3: Yes | M3: 2024 | N3: 3378202 | O3: 3034980008 | P3: 40.670746 | Q3: -73.912932
A4: ACS | B4: Chinese Community Concern Parents | C4: 180 Mott St | D4: Manhattan | E4: 10012 | F4: 17 | G4: 97095 | H4: Fair | I4: 20 years or more | J4: Not Solar-Ready | L4: Yes | M4: 2024 | N4: 1007156 | O4: 1004790001 | P4: 40.720558 | Q4: -73.995873
A5: ACS | B5: Blanche Community Progress Day Care Center 2 | C5: 44-22 Beach Channel Dr | D5: Queens | E5: 11691 | F5: 31 | G5: 27700 | H5: Between Fair and Poor | I5: 20 years or more | J5: Not Solar-Ready | L5: Yes | M5: 2024 | N5: 4463476 | O5: 4159670001 | P5: 40.59566 | Q5: -73.775979
A6: ACS | B6: Horizon Juvenile Center | C6: 560 Brook Ave | D6: Bronx | E6: 10455 | F6: 16 | G6: 20160 | H6: Between Good and Fair | I6: 20 years or more | J6: Not Solar-Ready | L6: Yes | M6: 2024 | N6: 2000133 | O6: 2022760001 | P6: 40.815878 | Q6: -73.914404
A7: ACS | B7: La Peninsula Head Start Program | C7: 1054 Intervale Ave | D7: Bronx | E7: 10459 | F7: 17 | G7: 20000 | H7: Between Good and Fair | I7: 20 years or more | J7: Not Solar-Ready | L7: Yes | M7: 2024 | N7: 2005481 | O7: 2027050009 | P7: 40.824823 | Q7: -73.896839
A8: ACS | B8: Blanche Day Care Center | C8: 109-60 202nd St | D8: Queens | E8: 11412 | F8: 27 | G8: 17590 | H8: Good | I8: 20 years or more | J8: Not Solar-Ready | L8: No | M8: 2024 | N8: 4234212 | O8: 4109410206 | P8: 40.706083 | Q8: -73.755417
A9: ACS | B9: ACS Administrative Site | C9: 150 William St | D9: Manhattan | E9: 10038 | F9: 33 | G9: 12685 | H9: Unknown | I9: 20 years or more | J9: Not Solar-Ready | L9: Yes | M9: 2024 | N9: 1001280 | O9: 1000930001 | P9: 40.709729 | Q9: -74.006255
A10: ACS | B10: Episcopal Social Services of NY (Space) | C10: 528 East 146th St | D10: Bronx | E10: 10455 | F10: 8 | H10: Unknown | I10: Unknown | J10: Not Solar-Ready | K10: No | L10: Yes | M10: 2022 | N10: 2093913 | O10: 2022720038 | P10: 40.812728 | Q10: -73.915397
A11: ACS | B11: 1250 East 229 Street | C11: 1250 East 229 St | D11: Bronx | E11: 10466 | F11: 12 | H11: Good | I11: Unknown | J11: Not Solar-Ready | K11: No | L11: Yes | M11: 2022 | N11: 2097408 | O11: 2049050002 | P11: 40.88372 | Q11: -73.842046
A12: ACS | B12: Babove Worldwide Institute Inc. | C12: 1810 Davidson Ave | D12: Bronx | E12: 10453 | F12: 14 | H12: Poor | I12: Unknown | J12: Not Solar-Ready | K12: No | L12: Yes | M12: 2022 | N12: 2109470 | O12: 2028610129 | P12: 40.849425 | Q12: -73.912268
A13: ACS | B13: Labor and Industry for Education Inc. | C13: 1375 Bushwick Ave | D13: Brooklyn | E13: 11207 | F13: 37 | H13: Poor | I13: Unknown | J13: Not Solar-Ready | K13: No | L13: Yes | M13: 2022 | N13: 3079655 | O13: 3034330005 | P13: 40.685173 | Q13: -73.910526
A14: ACS | B14: P.A.L. Miccio Day Care Center | C14: 595 Clinton Ave | D14: Brooklyn | F14: 38 | H14: Unknown | I14: Unknown | J14: Not Solar-Ready | K14: No | L14: Yes | M14: 2022
A15: ACS | B15: Friends of Crown Heights Educatiol Center | C15: 668 Logan St | D15: Brooklyn | E15: 11208 | F15: 42 | H15: Unknown | I15: Unknown | J15: Not Solar-Ready | K15: No | L15: Yes | M15: 2022 | N15: 3098472 | O15: 3044570001 | P15: 40.669503 | Q15: -73.874884
A16: ACS | B16: Childrens Aide Society Inc. | C16: 159 Broadway | D16: Staten Island | E16: 10310 | F16: 49 | H16: Poor | I16: Unknown | J16: Not Solar-Ready | K16: No | L16: Yes | M16: 2022 | N16: 5004830 | O16: 5001740006 | P16: 40.637531 | Q16: -74.117594
A17: BPL | B17: Central Library and Learning Center | C17: 10 Grand Army Plz | D17: Brooklyn | E17: 11238 | F17: 35 | G17: 352745 | H17: Between Good and Fair | I17: 20 years or more | J17: Solar-Ready | L17: No | M17: 2024 | N17: 3029665 | O17: 3011830002 | P17: 40.672833 | Q17: -73.969069
A18: BPL | B18: Brooklyn Heights Branch and Business Library | C18: 280 Cadman Plaza West | D18: Brooklyn | E18: 11201 | F18: 33 | G18: 62917 | H18: Good | I18: 2 to 4 years | J18: Not Solar-Ready | L18: No | M18: 2024 | N18: 3421378 | O18: 3002397501 | P18: 40.695649 | Q18: -73.991006
A19: BPL | B19: New Lots Branch Library | C19: 655 New Lots Ave | D19: Brooklyn | E19: 11207 | F19: 42 | G19: 24558 | H19: Poor | I19: 20 years or more | J19: Not Solar-Ready | L19: Yes | M19: 2024 | N19: 3090726 | O19: 3040900001 | P19: 40.664958 | Q19: -73.886017
A20: BPL | B20: Williamsburg Branch Library | C20: 240 Division Ave | D20: Brooklyn | E20: 11211 | F20: 33 | G20: 24118 | H20: Good | I20: 20 years or more | J20: Not Solar-Ready | L20: Yes | M20: 2024 | N20: 3060090 | O20: 3021890001 | P20: 40.707147 | Q20: -73.957335
A21: BPL | B21: Brooklyn Historical Society | C21: 128 Pierrepont St | D21: Brooklyn | E21: 11201 | F21: 33 | G21: 23545 | H21: Unknown | I21: Unknown | J21: Not Solar-Ready | L21: No | M21: 2024 | N21: 3002006 | O21: 3002430047 | P21: 40.69502 | Q21: -73.992387
A22: BPL | B22: New Utrecht Branch Library | C22: 1743 86th St | D22: Brooklyn | E22: 11214 | F22: 38 | G22: 22557 | H22: Good | I22: 20 years or more | J22: Not Solar-Ready | L22: No | M22: 2024 | N22: 3165745 | O22: 3063430064 | P22: 40.607852 | Q22: -74.003616
A23: BPL | B23: Flatbush Branch Library and Learning Center | C23: 22 Linden Blvd | D23: Brooklyn | E23: 11226 | F23: 40 | G23: 21790 | H23: Good | I23: 20 years or more | J23: Solar-Ready | L23: No | M23: 2024 | N23: 3116706 | O23: 3050860015 | P23: 40.652192 | Q23: -73.958177
A24: BPL | B24: Mapleton Branch Library | C24: 1703 60th St | D24: Brooklyn | E24: 11204 | F24: 44 | G24: 19821 | H24: Poor | I24: 20 years or more | J24: Not Solar-Ready | L24: No | M24: 2024 | P24: 40.623156 | Q24: -73.989114
A25: BPL | B25: Borough Park Branch Library | C25: 1265 43rd St | D25: Brooklyn | E25: 11219 | F25: 44 | G25: 19594 | H25: Good | I25: 20 years or more | J25: Not Solar-Ready | L25: No | M25: 2024 | N25: 3135907 | O25: 3055980048 | P25: 40.638914 | Q25: -73.989479
A26: BPL | B26: Kensington Branch Library | C26: 4207 18th Ave | D26: Brooklyn | E26: 11218 | F26: 40 | G26: 18300 | H26: Good | I26: 20 years or more | J26: Solar-Ready | L26: Yes | M26: 2024 | N26: 3416544 | O26: 3054160014 | P26: 40.631493 | Q26: -73.97557
A27: BPL | B27: Bedford Branch Library and Learning Center | C27: 496 Franklin Ave | D27: Brooklyn | E27: 11238 | F27: 36 | G27: 17184 | H27: Good | I27: 10 to 14 years | J27: Not Solar-Ready | L27: No | M27: 2024 | N27: 3057384 | O27: 3019970032 | P27: 40.681656 | Q27: -73.955786
A28: BPL | B28: Bay Ridge Branch Library | C28: 7223 Ridge Blvd | D28: Brooklyn | E28: 11209 | F28: 47 | G28: 16506 | H28: Good | I28: 20 years or more | J28: Not Solar-Ready | L28: No | M28: 2024 | N28: 3147279 | O28: 3059070001 | P28: 40.633942 | Q28: -74.029709
A29: BPL | B29: Arlington Branch Library | C29: 203 Arlington Ave | D29: Brooklyn | E29: 11207 | F29: 37 | G29: 16385 | H29: Good | I29: 5 to 9 years | J29: Not Solar-Ready | L29: Yes | M29: 2024 | N29: 3087001 | O29: 3039230052 | P29: 40.680475 | Q29: -73.887216
A30: BPL | B30: Eastern Parkway Branch Library and Learning Center | C30: 1044 Eastern Pkwy | D30: Brooklyn | E30: 11213 | F30: 35 | G30: 16024 | H30: Unknown | I30: 5 to 9 years | J30: Solar-Ready | L30: Yes | M30: 2024 | N30: 3037543 | O30: 3013960006 | P30: 40.668918 | Q30: -73.933427
A31: BPL | B31: Park Slope Branch Library | C31: 431 6th Ave | D31: Brooklyn | E31: 11215 | F31: 39 | G31: 15868 | H31: Good | I31: 5 to 9 years | J31: Not Solar-Ready | L31: No | M31: 2024 | N31: 3022144 | O31: 3010060001 | P31: 40.668422 | Q31: -73.983606
A32: BPL | B32: Pacific Branch Library | C32: 25 4th Ave | D32: Brooklyn | E32: 11217 | F32: 39 | G32: 15758 | H32: Good | I32: Unknown | J32: Not Solar-Ready | L32: No | M32: 2024 | N32: 3018376 | O32: 3009280006 | P32: 40.683666 | Q32: -73.978814
A33: BPL | B33: Midwood Branch Library | C33: 975 East 16th St | D33: Brooklyn | E33: 11230 | F33: 44 | G33: 15210 | H33: Good | I33: 20 years or more | J33: Not Solar-Ready | L33: No | M33: 2024 | N33: 3179706 | O33: 3067090054 | P33: 40.626054 | Q33: -73.9606
A34: BPL | B34: Kings Bay Branch Library | C34: 3651 Nostrand Ave | D34: Brooklyn | E34: 11229 | F34: 48 | G34: 14885 | H34: Between Fair and Poor | I34: 20 years or more | J34: Not Solar-Ready | L34: No | M34: 2024 | N34: 3344555 | O34: 3074051001 | P34: 40.59479 | Q34: -73.940789
A35: BPL | B35: Carroll Gardens Branch Library | C35: 396 Clinton St | D35: Brooklyn | E35: 11231 | F35: 39 | G35: 14779 | H35: Fair | I35: 20 years or more | J35: Not Solar-Ready | K35: Cool Roof | L35: No | M35: 2024 | N35: 3004336 | O35: 3003380033 | P35: 40.683265 | Q35: -73.997739
A36: BPL | B36: Stone Avenue Branch Library | C36: 581 Mother Gaston Blvd | D36: Brooklyn | E36: 11212 | F36: 41 | G36: 14258 | H36: Good | I36: 20 years or more | J36: Not Solar-Ready | L36: Yes | M36: 2024 | N36: 3084596 | O36: 3037940018 | P36: 40.664531 | Q36: -73.905532
A37: BPL | B37: DeKalb Branch Library | C37: 790 Bushwick Ave | D37: Brooklyn | E37: 11221 | F37: 34 | G37: 12584 | H37: Good | I37: 5 to 9 years | J37: Not Solar-Ready | L37: Yes | M37: 2024 | N37: 3073751 | O37: 3032410018 | P37: 40.695042 | Q37: -73.92815
A38: BPL | B38: East Flatbush Branch Library | C38: 9612 Church Ave | D38: Brooklyn | E38: 11212 | F38: 42 | G38: 12329 | H38: Good | I38: 2 to 4 years | J38: Not Solar-Ready | L38: Yes | M38: 2024 | N38: 3103597 | O38: 3047170038 | P38: 40.655816 | Q38: -73.915258
A39: BPL | B39: Brighton Beach Branch Library | C39: 16 Brighton 1st Rd | D39: Brooklyn | E39: 11235 | F39: 48 | G39: 12166 | H39: Good | I39: 5 to 9 years | J39: Not Solar-Ready | L39: No | M39: 2024 | N39: 3245028 | O39: 3086800032 | P39: 40.576172 | Q39: -73.966475
A40: BPL | B40: Flatlands Branch Library | C40: 2065 Flatbush Ave | D40: Brooklyn | E40: 11234 | F40: 45 | G40: 11903 | H40: Good | I40: 2 to 4 years | J40: Solar-Ready | K40: Cool Roof | L40: No | M40: 2024 | N40: 3219626 | O40: 3078680039 | P40: 40.619465 | Q40: -73.933404
...

Sheet Summary by Agency
A1: Agency | B1: # Buildings | C1: Total Gross Sq Ft
A2: ACS | B2: =COUNTIF(Buildings!$A$2:$A$2548,A2) -> 15 | C2: =SUMIF(Buildings!$A$2:$A$2548,A2,Buildings!$G$2:$G$2548) -> 737289
A3: BPL | B3: =COUNTIF(Buildings!$A$2:$A$2548,A3) -> 37 | C3: =SUMIF(Buildings!$A$2:$A$2548,A3,Buildings!$G$2:$G$2548) -> 870298
A4: CIG | B4: =COUNTIF(Buildings!$A$2:$A$2548,A4) -> 1 | C4: =SUMIF(Buildings!$A$2:$A$2548,A4,Buildings!$G$2:$G$2548) -> 13457
A5: CIG > BKM | B5: =COUNTIF(Buildings!$A$2:$A$2548,A5) -> 1 | C5: =SUMIF(Buildings!$A$2:$A$2548,A5,Buildings!$G$2:$G$2548) -> 0
A6: CIG > LCPA | B6: =COUNTIF(Buildings!$A$2:$A$2548,A6) -> 1 | C6: =SUMIF(Buildings!$A$2:$A$2548,A6,Buildings!$G$2:$G$2548) -> 0
A7: CIG > QBG | B7: =COUNTIF(Buildings!$A$2:$A$2548,A7) -> 1 | C7: =SUMIF(Buildings!$A$2:$A$2548,A7,Buildings!$G$2:$G$2548) -> 0
A8: CUNY | B8: =COUNTIF(Buildings!$A$2:$A$2548,A8) -> 73 | C8: =SUMIF(Buildings!$A$2:$A$2548,A8,Buildings!$G$2:$G$2548) -> 6518849
A9: DCAS | B9: =COUNTIF(Buildings!$A$2:$A$2548,A9) -> 54 | C9: =SUMIF(Buildings!$A$2:$A$2548,A9,Buildings!$G$2:$G$2548) -> 11155075
A10: DCAS > NA | B10: =COUNTIF(Buildings!$A$2:$A$2548,A10) -> 1 | C10: =SUMIF(Buildings!$A$2:$A$2548,A10,Buildings!$G$2:$G$2548) -> 0
A11: DCLA | B11: =COUNTIF(Buildings!$A$2:$A$2548,A11) -> 64 | C11: =SUMIF(Buildings!$A$2:$A$2548,A11,Buildings!$G$2:$G$2548) -> 2496627
A12: DEP | B12: =COUNTIF(Buildings!$A$2:$A$2548,A12) -> 50 | C12: =SUMIF(Buildings!$A$2:$A$2548,A12,Buildings!$G$2:$G$2548) -> 170841
A13: DEP > BPS | B13: =COUNTIF(Buildings!$A$2:$A$2548,A13) -> 2 | C13: =SUMIF(Buildings!$A$2:$A$2548,A13,Buildings!$G$2:$G$2548) -> 31900
... A36: SUNY | B36: =COUNTIF(Buildings!$A$2:$A$2548,A36) -> 2 | C36: =SUMIF(Buildings!$A$2:$A$2548,A36,Buildings!$G$2:$G$2548) -> 0
A37: TOTAL | B37: =SUM(B2:B36) -> 2547 | C37: =SUM(C2:C36) -> 1.9614467e+08

Sheet Source & Notes
A1: Source: NYC Open Data, 'City of New York Municipal Solar-Readiness Assessment (Local Law 24 of 2016) data', dataset cfz5-6fvh, https://data.cityofnewyork.us/d/cfz5-6fvh
A2: Pulled: 2026-09-02 via Socrata API. Publisher: DCAS Division of Energy Management.
A3: Scope: all City-owned buildings over 10,000 gross sq ft that DCAS is required to assess under LL24 (report years 2020, 2022, 2024).
A4: Dedup: one row per building (by BIN; by site+address where BIN missing), keeping the most recent report year.
A5: Row counts: 6,765 raw rows -> 2547 unique buildings (2268 from 2024 report; remainder appear only in 2020/2022).
A6: Gross Sq Ft blank = not reported in the source. Roof/solar fields are DCAS assessment values, not INOVUES data.
